<?xml version="1.0" encoding="UTF-8"?>
<!-- Generated by org.testng.reporters.JUnitXMLReporter -->
<testsuite hostname="LAPTOP-PFAQCIOF" name="test" tests="5" failures="3" timestamp="17 Nov 2020 14:05:30 GMT" time="0.022" errors="0">
  <testcase name="test1" time="0.007" classname="com.webtest.demo.Demo"/>
  <testcase name="test2" time="0.001" classname="com.webtest.demo.Demo">
    <failure type="java.lang.AssertionError" message="expected [1] but found [2]">
      <![CDATA[java.lang.AssertionError: expected [1] but found [2]
	at com.webtest.demo.Demo.test2(Demo.java:13)
	at com.intellij.rt.testng.IDEARemoteTestNG.run(IDEARemoteTestNG.java:66)
	at com.intellij.rt.testng.RemoteTestNGStarter.main(RemoteTestNGStarter.java:110)
... Removed 26 stack frames]]>
    </failure>
  </testcase> <!-- test2 -->
  <testcase name="test3" time="0.0" classname="com.webtest.demo.Demo">
    <failure type="java.lang.AssertionError" message="expected [1] but found [3]">
      <![CDATA[java.lang.AssertionError: expected [1] but found [3]
	at com.webtest.demo.Demo.test3(Demo.java:17)
	at com.intellij.rt.testng.IDEARemoteTestNG.run(IDEARemoteTestNG.java:66)
	at com.intellij.rt.testng.RemoteTestNGStarter.main(RemoteTestNGStarter.java:110)
... Removed 26 stack frames]]>
    </failure>
  </testcase> <!-- test3 -->
  <testcase name="test4" time="0.0" classname="com.webtest.demo.Demo"/>
  <testcase name="test5" time="0.001" classname="com.webtest.demo.Demo">
    <failure type="java.lang.AssertionError" message="expected [2] but found [3]">
      <![CDATA[java.lang.AssertionError: expected [2] but found [3]
	at com.webtest.demo.Demo.test5(Demo.java:25)
	at com.intellij.rt.testng.IDEARemoteTestNG.run(IDEARemoteTestNG.java:66)
	at com.intellij.rt.testng.RemoteTestNGStarter.main(RemoteTestNGStarter.java:110)
... Removed 26 stack frames]]>
    </failure>
  </testcase> <!-- test5 -->
</testsuite> <!-- test -->
