<?xml version="1.0" encoding="UTF-8"?>
<!-- Generated by org.testng.reporters.JUnitXMLReporter -->
<testsuite hostname="LAPTOP-PFAQCIOF" ignored="0" name="t2" tests="5" failures="3" timestamp="16 十一月 2020 06:36:34 GMT" time="0.034" errors="0">
  <testcase name="test1" time="0.011" classname="com.webtest.demo.Demo"/>
  <testcase name="test2" time="0.001" classname="com.webtest.demo.Demo">
    <failure type="java.lang.AssertionError" message="expected [1] but found [2]">
      <![CDATA[java.lang.AssertionError: expected [1] but found [2]
at com.webtest.demo.Demo.test2(Demo.java:17)
at com.intellij.rt.testng.IDEARemoteTestNG.run(IDEARemoteTestNG.java:66)
at com.intellij.rt.testng.RemoteTestNGStarter.main(RemoteTestNGStarter.java:110)
... Removed 28 stack frames]]>
    </failure>
  </testcase> <!-- test2 -->
  <testcase name="test3" time="0.0" classname="com.webtest.demo.Demo">
    <failure type="java.lang.AssertionError" message="expected [1] but found [3]">
      <![CDATA[java.lang.AssertionError: expected [1] but found [3]
at com.webtest.demo.Demo.test3(Demo.java:21)
at com.intellij.rt.testng.IDEARemoteTestNG.run(IDEARemoteTestNG.java:66)
at com.intellij.rt.testng.RemoteTestNGStarter.main(RemoteTestNGStarter.java:110)
... Removed 28 stack frames]]>
    </failure>
  </testcase> <!-- test3 -->
  <testcase name="test4" time="0.0" classname="com.webtest.demo.Demo"/>
  <testcase name="test5" time="0.0" classname="com.webtest.demo.Demo">
    <failure type="java.lang.AssertionError" message="expected [1] but found [4]">
      <![CDATA[java.lang.AssertionError: expected [1] but found [4]
at com.webtest.demo.Demo.test5(Demo.java:29)
at com.intellij.rt.testng.IDEARemoteTestNG.run(IDEARemoteTestNG.java:66)
at com.intellij.rt.testng.RemoteTestNGStarter.main(RemoteTestNGStarter.java:110)
... Removed 28 stack frames]]>
    </failure>
  </testcase> <!-- test5 -->
</testsuite> <!-- t2 -->
